Workbook

Sheet Resumen
A1: MI CARTERA · DEMO
A2: Datos ficticios de ejemplo · importes en euros
A3: Cartera por posiciones | C3: =Cartera!B17 -> 85387
A4: Último valor del diario | C4: =IFERROR(LOOKUP(2,1/((Diario!B6:B370<>"")*(Diario!A6:A370<=TODAY())),Diario!B6:B370),"") -> 85387
A5: Capital neto desde la base | C5: =IF(C6="","",Evolucion!$C$3+SUMIFS(Movimientos!B6:B505,Movimientos!D6:D505,"<="&C6,Movimientos!D6:D505,">="&DATE(2025,2,1))) -> 63896
A6: Último registro | C6: =IFERROR(LOOKUP(2,1/((Diario!B6:B370<>"")*(Diario!A6:A370<=TODAY())),Diario!A6:A370),"") -> 46275
A7: Ganancia desde la base | C7: =IF(C4="","",C4-C5) -> 21491
A8: Mes abierto (provisional) | C8: =TEXT(TODAY(),"mmmm aaaa") -> septiembre 2026
A9: Último mes en estadísticas | C9: =IFERROR(__xludf.DUMMYFUNCTION("IFERROR(INDEX(FILTER('Estadísticas avanzadas'!A77:A98,ISNUMBER('Estadísticas avanzadas'!B77:B98)),COUNT('Estadísticas avanzadas'!B77:B98)),"""")"),"2026 Ago") -> 2026 Ago
A10: Meses completos | C10: ='Estadísticas avanzadas'!I55 -> 18
A11: Control de datos | C11: =Control!C14 -> OK
A12: =IF(C11="OK","Sin incidencias detectadas.",_xludf.TEXTJOIN(CHAR(10),TRUE,IF(ABS(Control!C12)>1/100,"Diferencia Cartera − Diario: "&TEXT(Control!C12,"0")&" €.",""),IF(Control!C11>0,Control!C11&" movimientos históricos sin fecha utilizable.",""),IF(C11="REVISAR","Hay controles pendientes: abre Revisar controles.",""))) -> Sin incidencias detectadas.
A13: Registra el valor de hoy en Diario
A14: Añade aportaciones o retiradas en Movimientos
A15: Ajusta pesos y próxima aportación en Objetivos
A16: Revisa la calidad de los datos en Control
A17: ESTADÍSTICAS · MESES COMPLETOS
A18: Sortino | C18: ='Estadísticas avanzadas'!E49 -> 4.4453847
A19: Sharpe | C19: ='Estadísticas avanzadas'!A49 -> 2.3028731
A20: Beta vs MSCI World | C20: ='Estadísticas avanzadas'!M49 -> 0.28397956
A21: Tracking error anual | C21: ='Estadísticas avanzadas'!I52 -> 0.12147204
A22: Information ratio | C22: ='Estadísticas avanzadas'!E52 -> 0.81089411
A23: Treynor | C23: ='Estadísticas avanzadas'!A58 -> 0.71742591
A24: Alpha anual | C24: ='Estadísticas avanzadas'!I49 -> 0.17385018
A25: Rentabilidad anualizada | C25: ='Estadísticas avanzadas'!A55 -> 0.25283895
A26: Volatilidad anualizada | C26: ='Estadísticas avanzadas'!E55 -> 0.088469613
A27: Máximo drawdown mensual | C27: ='Estadísticas avanzadas'!A52 -> -0.056746077
A28: Correlación | C28: ='Estadísticas avanzadas'!M52 -> 0.40649275
A29: Objetivo anual de Sortino | C29: ='Estadísticas avanzadas'!C43 -> 0.0275
A30: Meses por debajo del objetivo | C30: =COUNTIF('Estadísticas avanzadas'!J77:J98,"<0") -> 4
A31: Proporción bajo objetivo | C31: =IFERROR(C30/C10,"") -> 0.22222222
A32: Muestra corta: los ratios pueden variar mucho.
A33: AHORRO Y GANANCIA · DESDE FEB 2025

Sheet Cartera
A1: Activo | B1: Importe (€) | C1: Peso %
A2: ETF Global Desarrollado | B2: 20000 | C2: =B2/$B$17 -> 0.23422769
A3: ETF Mercados Emergentes | B3: 7000 | C3: =B3/$B$17 -> 0.081979692
A4: Fondo Asia Pacífico | B4: 2500 | C4: =B4/$B$17 -> 0.029278462
A5: Fondo Value Global | B5: 7500 | C5: =B5/$B$17 -> 0.087835385
A6: Fondo Internacional A | B6: 5000 | C6: =B6/$B$17 -> 0.058556923
A7: Fondo Internacional B | B7: 2000 | C7: =B7/$B$17 -> 0.023422769
A8: Fondo Crédito Flexible | B8: 5000 | C8: =B8/$B$17 -> 0.058556923
A9: Fondo Mixto Defensivo | B9: 8500 | C9: =B9/$B$17 -> 0.099546769
A10: Fondo Retorno Absoluto | B10: 3000 | C10: =B10/$B$17 -> 0.035134154
A11: Cuenta de efectivo | B11: 1387 | C11: =B11/$B$17 -> 0.01624369
A12: Acción tecnológica | B12: 15000 | C12: =B12/$B$17 -> 0.17567077
A13: Acción industrial | B13: 1800 | C13: =B13/$B$17 -> 0.021080492
... A16: Bitcoin | B16: 1000 | C16: =B16/$B$17 -> 0.011711385
A17: TOTAL | B17: =SUM(B2:B16) -> 85387

Sheet Evolucion
A1: 2025
A2: Mes | B2: Valor Total | C2: Capital Inicial | D2: Capital Aportado | E2: Plusvalías | F2: % mes / simple YTD | G2: TWR acumulado | N2: Periodo | O2: Valor Total | P2: Capital invertido estimado | Q2: Plusvalía estimada | T2: Mes | U2: Valor Total | V2: Capital invertido | W2: Plusvalías acumuladas
A3: Feb | B3: 52428 | C3: =51728 -> 51728 | D3: =IF(AND(B3="",COUNTIFS(Movimientos!$D$6:$D$505,">="&DATE(2025,2,1),Movimientos!$D$6:$D$505,"<"&DATE(2025,3,1))=0),"",SUMIFS(Movimientos!$B$6:$B$505,Movimientos!$D$6:$D$505,">="&DATE(2025,2,1),Movimientos!$D$6:$D$505,"<"&DATE(2025,3,1))) -> 700 | N3: ="2025 "&A3 -> 2025 Feb | O3: =B3 -> 52428 | P3: =C3+SUM(D3) -> 52428 | Q3: =O3-P3 -> 0 | T3: =A3 -> Feb | U3: =IF(B3="","",B3) -> 52428 | V3: =IF(B3="","",$C$3+SUM($D$3:D3)) -> 52428 | W3: =IF(U3="","",U3-V3) -> 0
A4: Mar | B4: 55139 | C4: 52428 | D4: =IF(AND(B4="",COUNTIFS(Movimientos!$D$6:$D$505,">="&DATE(2025,3,1),Movimientos!$D$6:$D$505,"<"&DATE(2025,4,1))=0),"",SUMIFS(Movimientos!$B$6:$B$505,Movimientos!$D$6:$D$505,">="&DATE(2025,3,1),Movimientos!$D$6:$D$505,"<"&DATE(2025,4,1))) -> 700 | E4: =B4-C4-D4 -> 2011 | F4: =IF(OR(B4="",C4=0),"",((B4-IF(D4="",0,D4))/C4-1)*100) -> 3.8357366 | G4: =IF(F4="","",F4) -> 3.8357366 | N4: ="2025 "&A4 -> 2025 Mar | O4: =B4 -> 55139 | P4: =C3+SUM(D3:D4) -> 53128 | Q4: =O4-P4 -> 2011 | T4: =A4 -> Mar | U4: =IF(B4="","",B4) -> 55139 | V4: =IF(B4="","",$C$3+SUM($D$3:D4)) -> 53128 | W4: =IF(U4="","",U4-V4) -> 2011
A5: Abr | B5: 57033 | C5: 55139 | D5: =IF(AND(B5="",COUNTIFS(Movimientos!$D$6:$D$505,">="&DATE(2025,4,1),Movimientos!$D$6:$D$505,"<"&DATE(2025,5,1))=0),"",SUMIFS(Movimientos!$B$6:$B$505,Movimientos!$D$6:$D$505,">="&DATE(2025,4,1),Movimientos!$D$6:$D$505,"<"&DATE(2025,5,1))) -> 700 | E5: =B5-C5-D5 -> 1194 | F5: =IF(OR(B5="",C5=0),"",((B5-IF(D5="",0,D5))/C5-1)*100) -> 2.1654364 | G5: =IF(F5="","",((1+G4/100)*(1+F5/100)-1)*100) -> 6.0842335 | N5: ="2025 "&A5 -> 2025 Abr | O5: =B5 -> 57033 | P5: =C3+SUM(D3:D5) -> 53828 | Q5: =O5-P5 -> 3205 | T5: =A5 -> Abr | U5: =IF(B5="","",B5) -> 57033 | V5: =IF(B5="","",$C$3+SUM($D$3:D5)) -> 53828 | W5: =IF(U5="","",U5-V5) -> 3205
A6: May | B6: 59028 | C6: 57033 | D6: =IF(AND(B6="",COUNTIFS(Movimientos!$D$6:$D$505,">="&DATE(2025,5,1),Movimientos!$D$6:$D$505,"<"&DATE(2025,6,1))=0),"",SUMIFS(Movimientos!$B$6:$B$505,Movimientos!$D$6:$D$505,">="&DATE(2025,5,1),Movimientos!$D$6:$D$505,"<"&DATE(2025,6,1))) -> 700 | E6: =B6-C6-D6 -> 1295 | F6: =IF(OR(B6="",C6=0),"",((B6-IF(D6="",0,D6))/C6-1)*100) -> 2.2706153 | G6: =IF(F6="","",((1+G5/100)*(1+F6/100)-1)*100) -> 8.4929983 | N6: ="2025 "&A6 -> 2025 May | O6: =B6 -> 59028 | P6: =C3+SUM(D3:D6) -> 54528 | Q6: =O6-P6 -> 4500 | T6: =A6 -> May | U6: =IF(B6="","",B6) -> 59028 | V6: =IF(B6="","",$C$3+SUM($D$3:D6)) -> 54528 | W6: =IF(U6="","",U6-V6) -> 4500
A7: Jun | B7: 60385 | C7: 59028 | D7: =IF(AND(B7="",COUNTIFS(Movimientos!$D$6:$D$505,">="&DATE(2025,6,1),Movimientos!$D$6:$D$505,"<"&DATE(2025,7,1))=0),"",SUMIFS(Movimientos!$B$6:$B$505,Movimientos!$D$6:$D$505,">="&DATE(2025,6,1),Movimientos!$D$6:$D$505,"<"&DATE(2025,7,1))) -> 700 | E7: =B7-C7-D7 -> 657 | F7: =IF(OR(B7="",C7=0),"",((B7-IF(D7="",0,D7))/C7-1)*100) -> 1.1130311 | G7: =IF(F7="","",((1+G6/100)*(1+F7/100)-1)*100) -> 9.7005591 | N7: ="2025 "&A7 -> 2025 Jun | O7: =B7 -> 60385 | P7: =C3+SUM(D3:D7) -> 55228 | Q7: =O7-P7 -> 5157 | T7: =A7 -> Jun | U7: =IF(B7="","",B7) -> 60385 | V7: =IF(B7="","",$C$3+SUM($D$3:D7)) -> 55228 | W7: =IF(U7="","",U7-V7) -> 5157
A8: Jul | B8: 61988 | C8: 60385 | D8: =IF(AND(B8="",COUNTIFS(Movimientos!$D$6:$D$505,">="&DATE(2025,7,1),Movimientos!$D$6:$D$505,"<"&DATE(2025,8,1))=0),"",SUMIFS(Movimientos!$B$6:$B$505,Movimientos!$D$6:$D$505,">="&DATE(2025,7,1),Movimientos!$D$6:$D$505,"<"&DATE(2025,8,1))) -> 700 | E8: =B8-C8-D8 -> 903 | F8: =IF(OR(B8="",C8=0),"",((B8-IF(D8="",0,D8))/C8-1)*100) -> 1.4954045 | G8: =IF(F8="","",((1+G7/100)*(1+F8/100)-1)*100) -> 11.341026 | N8: ="2025 "&A8 -> 2025 Jul | O8: =B8 -> 61988 | P8: =C3+SUM(D3:D8) -> 55928 | Q8: =O8-P8 -> 6060 | T8: =A8 -> Jul | U8: =IF(B8="","",B8) -> 61988 | V8: =IF(B8="","",$C$3+SUM($D$3:D8)) -> 55928 | W8: =IF(U8="","",U8-V8) -> 6060
A9: Ago | B9: 63184 | C9: 61988 | D9: =IF(AND(B9="",COUNTIFS(Movimientos!$D$6:$D$505,">="&DATE(2025,8,1),Movimientos!$D$6:$D$505,"<"&DATE(2025,9,1))=0),"",SUMIFS(Movimientos!$B$6:$B$505,Movimientos!$D$6:$D$505,">="&DATE(2025,8,1),Movimientos!$D$6:$D$505,"<"&DATE(2025,9,1))) -> 700 | E9: =B9-C9-D9 -> 496 | F9: =IF(OR(B9="",C9=0),"",((B9-IF(D9="",0,D9))/C9-1)*100) -> 0.80015487 | G9: =IF(F9="","",((1+G8/100)*(1+F9/100)-1)*100) -> 12.231927 | N9: ="2025 "&A9 -> 2025 Ago | O9: =B9 -> 63184 | P9: =C3+SUM(D3:D9) -> 56628 | Q9: =O9-P9 -> 6556 | T9: =A9 -> Ago | U9: =IF(B9="","",B9) -> 63184 | V9: =IF(B9="","",$C$3+SUM($D$3:D9)) -> 56628 | W9: =IF(U9="","",U9-V9) -> 6556
A10: Sep | B10: 67169 | C10: 63184 | D10: =IF(AND(B10="",COUNTIFS(Movimientos!$D$6:$D$505,">="&DATE(2025,9,1),Movimientos!$D$6:$D$505,"<"&DATE(2025,10,1))=0),"",SUMIFS(Movimientos!$B$6:$B$505,Movimientos!$D$6:$D$505,">="&DATE(2025,9,1),Movimientos!$D$6:$D$505,"<"&DATE(2025,10,1))) -> 700 | E10: =B10-C10-D10 -> 3285 | F10: =IF(OR(B10="",C10=0),"",((B10-IF(D10="",0,D10))/C10-1)*100) -> 5.199101 | G10: =IF(F10="","",((1+G9/100)*(1+F10/100)-1)*100) -> 18.066978 | N10: ="2025 "&A10 -> 2025 Sep | O10: =B10 -> 67169 | P10: =C3+SUM(D3:D10) -> 57328 | Q10: =O10-P10 -> 9841 | T10: =A10 -> Sep | U10: =IF(B10="","",B10) -> 67169 | V10: =IF(B10="","",$C$3+SUM($D$3:D10)) -> 57328 | W10: =IF(U10="","",U10-V10) -> 9841
A11: Oct | B11: 69786 | C11: 67169 | D11: =IF(AND(B11="",COUNTIFS(Movimientos!$D$6:$D$505,">="&DATE(2025,10,1),Movimientos!$D$6:$D$505,"<"&DATE(2025,11,1))=0),"",SUMIFS(Movimientos!$B$6:$B$505,Movimientos!$D$6:$D$505,">="&DATE(2025,10,1),Movimientos!$D$6:$D$505,"<"&DATE(2025,11,1))) -> 700 | E11: =B11-C11-D11 -> 1917 | F11: =IF(OR(B11="",C11=0),"",((B11-IF(D11="",0,D11))/C11-1)*100) -> 2.8539951 | G11: =IF(F11="","",((1+G10/100)*(1+F11/100)-1)*100) -> 21.436604 | N11: ="2025 "&A11 -> 2025 Oct | O11: =B11 -> 69786 | P11: =C3+SUM(D3:D11) -> 58028 | Q11: =O11-P11 -> 11758 | T11: =A11 -> Oct | U11: =IF(B11="","",B11) -> 69786 | V11: =IF(B11="","",$C$3+SUM($D$3:D11)) -> 58028 | W11: =IF(U11="","",U11-V11) -> 11758
A12: Nov | B12: 70299 | C12: 69786 | D12: =IF(AND(B12="",COUNTIFS(Movimientos!$D$6:$D$505,">="&DATE(2025,11,1),Movimientos!$D$6:$D$505,"<"&DATE(2025,12,1))=0),"",SUMIFS(Movimientos!$B$6:$B$505,Movimientos!$D$6:$D$505,">="&DATE(2025,11,1),Movimientos!$D$6:$D$505,"<"&DATE(2025,12,1))) -> 700 | E12: =B12-C12-D12 -> -187 | F12: =IF(OR(B12="",C12=0),"",((B12-IF(D12="",0,D12))/C12-1)*100) -> -0.26796206 | G12: =IF(F12="","",((1+G11/100)*(1+F12/100)-1)*100) -> 21.1112 | N12: ="2025 "&A12 -> 2025 Nov | O12: =B12 -> 70299 | P12: =C3+SUM(D3:D12) -> 58728 | Q12: =O12-P12 -> 11571 | T12: =A12 -> Nov | U12: =IF(B12="","",B12) -> 70299 | V12: =IF(B12="","",$C$3+SUM($D$3:D12)) -> 58728 | W12: =IF(U12="","",U12-V12) -> 11571
A13: Dic | B13: 73708 | C13: 70299 | D13: =IF(AND(B13="",COUNTIFS(Movimientos!$D$6:$D$505,">="&DATE(2025,12,1),Movimientos!$D$6:$D$505,"<"&DATE(2025,13,1))=0),"",SUMIFS(Movimientos!$B$6:$B$505,Movimientos!$D$6:$D$505,">="&DATE(2025,12,1),Movimientos!$D$6:$D$505,"<"&DATE(2025,13,1))) -> 700 | E13: =B13-C13-D13 -> 2709 | F13: =IF(OR(B13="",C13=0),"",((B13-IF(D13="",0,D13))/C13-1)*100) -> 3.8535399 | G13: =IF(F13="","",((1+G12/100)*(1+F13/100)-1)*100) -> 25.778268 | N13: ="2025 "&A13 -> 2025 Dic | O13: =B13 -> 73708 | P13: =C3+SUM(D3:D13) -> 59428 | Q13: =O13-P13 -> 14280 | T13: =A13 -> Dic | U13: =IF(B13="","",B13) -> 73708 | V13: =IF(B13="","",$C$3+SUM($D$3:D13)) -> 59428 | W13: =IF(U13="","",U13-V13) -> 14280
A14: YTD 2025 | B14: =B13 -> 73708 | C14: =C3 -> 51728 | D14: =SUM(D3:D13) -> 7700 | E14: =SUM(E4:E13) -> 14280 | F14: =IF(OR(B14="",C14=0),"",(B14-C14-D14)/C14) -> 0.27605939 | G14: =IFERROR(__xludf.DUMMYFUNCTION("IFERROR(INDEX(FILTER(G4:G13,ISNUMBER(G4:G13)),COUNT(FILTER(G4:G13,ISNUMBER(G4:G13)))),"""")"),25.7782683126974) -> 25.778268 | N14: ="2026 "&A19 -> 2026 Ene | O14: =B19 -> 76000 | P14: =C3+SUM(D3:D13)+SUM(D19) -> 59928 | Q14: =O14-P14 -> 16072
A15: Volatilidad mensual | B15: =IFERROR(__xludf.DUMMYFUNCTION("IFERROR(STDEV(FILTER(F4:F13,ISNUMBER(F4:F13)))*SQRT(12)/100,"""")"),0.0570294609061031) -> 0.057029461 | C15: =IFERROR(__xludf.DUMMYFUNCTION("""Mensual · ""&COUNT(FILTER(F4:F13,ISNUMBER(F4:F13)))&"" meses"""),"Mensual · 10 meses") -> Mensual · 10 meses | N15: ="2026 "&A20 -> 2026 Feb | O15: =B20 -> 76422 | P15: =C3+SUM(D3:D13)+SUM(D19:D20) -> 60628 | Q15: =O15-P15 -> 15794
N16: ="2026 "&A21 -> 2026 Mar | O16: =B21 -> 72950 | P16: =C3+SUM(D3:D13)+SUM(D19:D21) -> 61228 | Q16: =O16-P16 -> 11722
A17: 2026 | N17: ="2026 "&A22 -> 2026 Abr | O17: =B22 -> 76207 | P17: =C3+SUM(D3:D13)+SUM(D19:D22) -> 60528 | Q17: =O17-P17 -> 15679 | T17: Mes | U17: Valor Total | V17: Capital invertido | W17: Plusvalías acumuladas
A18: Mes | B18: Valor Total | C18: Capital Inicial | D18: Capital Aportado | E18: Plusvalías | F18: % mes / simple YTD | G18: TWR acumulado | N18: ="2026 "&A23 -> 2026 May | O18: =B23 -> 79485 | P18: =C3+SUM(D3:D13)+SUM(D19:D23) -> 59828 | Q18: =O18-P18 -> 19657 | T18: =A19 -> Ene | U18: =IF(B19="","",B19) -> 76000 | V18: =IF(U18="","",$C$19+SUM($D$19:D19)) -> 74208 | W18: =IF(U18="","",U18-V18) -> 1792
A19: Ene | B19: 76000 | C19: =73708 -> 73708 | D19: =IF(AND(B19="",COUNTIFS(Movimientos!$D$6:$D$505,">="&DATE(2026,1,1),Movimientos!$D$6:$D$505,"<"&DATE(2026,2,1))=0),"",SUMIFS(Movimientos!$B$6:$B$505,Movimientos!$D$6:$D$505,">="&DATE(2026,1,1),Movimientos!$D$6:$D$505,"<"&DATE(2026,2,1))) -> 500 | E19: =B19-C19-D19 -> 1792 | F19: =IF(OR(B19="",C19=0),"",((B19-IF(D19="",0,D19))/C19-1)*100) -> 2.4312151 | G19: =IF(F19="","",F19) -> 2.4312151 | N19: ="2026 "&A24 -> 2026 Jun | O19: =B24 -> 76115 | P19: =IF(O19="","",C3+SUM(D3:D13)+SUM(D19:D24)) -> 56388 | Q19: =IF(O19="","",O19-P19) -> 19727 | T19: =A20 -> Feb | U19: =IF(B20="","",B20) -> 76422 | V19: =IF(U19="","",$C$19+SUM($D$19:D20)) -> 74908 | W19: =IF(U19="","",U19-V19) -> 1514
A20: Feb | B20: 76422 | C20: =B19 -> 76000 | D20: =IF(AND(B20="",COUNTIFS(Movimientos!$D$6:$D$505,">="&DATE(2026,2,1),Movimientos!$D$6:$D$505,"<"&DATE(2026,3,1))=0),"",SUMIFS(Movimientos!$B$6:$B$505,Movimientos!$D$6:$D$505,">="&DATE(2026,2,1),Movimientos!$D$6:$D$505,"<"&DATE(2026,3,1))) -> 700 | E20: =B20-C20-D20 -> -278 | F20: =IF(OR(B20="",C20=0),"",((B20-IF(D20="",0,D20))/C20-1)*100) -> -0.36578947 | G20: =IF(F20="","",((1+G19/100)*(1+F20/100)-1)*100) -> 2.0565325 | N20: ="2026 "&A25 -> 2026 Jul | O20: =B25 -> 83862 | P20: =IF(O20="","",C3+SUM(D3:D13)+SUM(D19:D25)) -> 62388 | Q20: =IF(O20="","",O20-P20) -> 21474 | T20: =A21 -> Mar | U20: =IF(B21="","",B21) -> 72950 | V20: =IF(U20="","",$C$19+SUM($D$19:D21)) -> 75508 | W20: =IF(U20="","",U20-V20) -> -2558
A21: Mar | B21: 72950 | C21: =B20 -> 76422 | D21: =IF(AND(B21="",COUNTIFS(Movimientos!$D$6:$D$505,">="&DATE(2026,3,1),Movimientos!$D$6:$D$505,"<"&DATE(2026,4,1))=0),"",SUMIFS(Movimientos!$B$6:$B$505,Movimientos!$D$6:$D$505,">="&DATE(2026,3,1),Movimientos!$D$6:$D$505,"<"&DATE(2026,4,1))) -> 600 | E21: =B21-C21-D21 -> -4072 | F21: =IF(OR(B21="",C21=0),"",((B21-IF(D21="",0,D21))/C21-1)*100) -> -5.3283086 | G21: =IF(F21="","",((1+G20/100)*(1+F21/100)-1)*100) -> -3.3813545 | N21: ="2026 "&A26 -> 2026 Ago | O21: =B26 -> 86713 | P21: =IF(O21="","",C3+SUM(D3:D13)+SUM(D19:D26)) -> 63896 | Q21: =IF(O21="","",O21-P21) -> 22817 | T21: =A22 -> Abr | U21: =IF(B22="","",B22) -> 76207 | V21: =IF(U21="","",$C$19+SUM($D$19:D22)) -> 74808 | W21: =IF(U21="","",U21-V21) -> 1399
A22: Abr | B22: 76207 | C22: =B21 -> 72950 | D22: =IF(AND(B22="",COUNTIFS(Movimientos!$D$6:$D$505,">="&DATE(2026,4,1),Movimientos!$D$6:$D$505,"<"&DATE(2026,5,1))=0),"",SUMIFS(Movimientos!$B$6:$B$505,Movimientos!$D$6:$D$505,">="&DATE(2026,4,1),Movimientos!$D$6:$D$505,"<"&DATE(2026,5,1))) -> -700 | E22: =B22-C22-D22 -> 3957 | F22: =IF(OR(B22="",C22=0),"",((B22-IF(D22="",0,D22))/C22-1)*100) -> 5.4242632 | G22: =IF(F22="","",((1+G21/100)*(1+F22/100)-1)*100) -> 1.8594951 | N22: ="2026 "&A27 -> 2026 Sep | O22: =B27 -> 85387 | P22: =IF(O22="","",C3+SUM(D3:D13)+SUM(D19:D27)) -> 63896 | Q22: =IF(O22="","",O22-P22) -> 21491 | T22: =A23 -> May | U22: =IF(B23="","",B23) -> 79485 | V22: =IF(U22="","",$C$19+SUM($D$19:D23)) -> 74108 | W22: =IF(U22="","",U22-V22) -> 5377
A23: May | B23: 79485 | C23: =B22 -> 76207 | D23: =IF(AND(B23="",COUNTIFS(Movimientos!$D$6:$D$505,">="&DATE(2026,5,1),Movimientos!$D$6:$D$505,"<"&DATE(2026,6,1))=0),"",SUMIFS(Movimientos!$B$6:$B$505,Movimientos!$D$6:$D$505,">="&DATE(2026,5,1),Movimientos!$D$6:$D$505,"<"&DATE(2026,6,1))) -> -700 | E23: =B23-C23-D23 -> 3978 | F23: =IF(OR(B23="",C23=0),"",((B23-IF(D23="",0,D23))/C23-1)*100) -> 5.2199929 | G23: =IF(F23="","",((1+G22/100)*(1+F23/100)-1)*100) -> 7.1765535 | N23: ="2026 "&A28 -> 2026 Oct | O23: =B28 | P23: =IF(O23="","",C3+SUM(D3:D13)+SUM(D19:D28)) | Q23: =IF(O23="","",O23-P23) | T23: =A24 -> Jun | U23: =IF(B24="","",B24) -> 76115 | V23: =IF(U23="","",$C$19+SUM($D$19:D24)) -> 70668 | W23: =IF(U23="","",U23-V23) -> 5447
A24: Jun | B24: 76115 | C24: =B23 -> 79485 | D24: =IF(AND(B24="",COUNTIFS(Movimientos!$D$6:$D$505,">="&DATE(2026,6,1),Movimientos!$D$6:$D$505,"<"&DATE(2026,7,1))=0),"",SUMIFS(Movimientos!$B$6:$B$505,Movimientos!$D$6:$D$505,">="&DATE(2026,6,1),Movimientos!$D$6:$D$505,"<"&DATE(2026,7,1))) -> -3440 | E24: =B24-C24-D24 -> 70 | F24: =IF(OR(B24="",C24=0),"",((B24-IF(D24="",0,D24))/C24-1)*100) -> 0.088066931 | G24: =IF(F24="","",((1+G23/100)*(1+F24/100)-1)*100) -> 7.2709406 | N24: ="2026 "&A29 -> 2026 Nov | O24: =B29 | P24: =IF(O24="","",C3+SUM(D3:D13)+SUM(D19:D29)) | Q24: =IF(O24="","",O24-P24) | T24: =A25 -> Jul | U24: =IF(B25="","",B25) -> 83862 | V24: =IF(U24="","",$C$19+SUM($D$19:D25)) -> 76668 | W24: =IF(U24="","",U24-V24) -> 7194
A25: Jul | B25: =IFERROR(__xludf.DUMMYFUNCTION("IFERROR(XLOOKUP(MAX(FILTER('Datos diarios'!$A$2:$A$366,'Datos diarios'!$A$2:$A$366>=DATE(2026,7,1),'Datos diarios'!$A$2:$A$366<DATE(2026,8,1),'Datos diarios'!$B$2:$B$366<>"""")),'Datos diarios'!$A$2:$A$366,'Datos diarios'!$B$2:$B$366,""""),"""")"),83862) -> 83862 | C25: =B24 -> 76115 | D25: =IF(AND(B25="",COUNTIFS(Movimientos!$D$6:$D$505,">="&DATE(2026,7,1),Movimientos!$D$6:$D$505,"<"&DATE(2026,8,1))=0),"",SUMIFS(Movimientos!$B$6:$B$505,Movimientos!$D$6:$D$505,">="&DATE(2026,7,1),Movimientos!$D$6:$D$505,"<"&DATE(2026,8,1))) -> 6000 | E25: =B25-C25-D25 -> 1747 | F25: =IF(OR(B25="",C25=0),"",((B25-IF(D25="",0,D25))/C25-1)*100) -> 2.2952112 | G25: =IF(F25="","",((1+G24/100)*(1+F25/100)-1)*100) -> 9.7330353 | N25: ="2026 "&A30 -> 2026 Dic | O25: =B30 | P25: =IF(O25="","",C3+SUM(D3:D13)+SUM(D19:D30)) | Q25: =IF(O25="","",O25-P25) | T25: =A26 -> Ago | U25: =IF(B26="","",B26) -> 86713 | V25: =IF(U25="","",$C$19+SUM($D$19:D26)) -> 78176 | W25: =IF(U25="","",U25-V25) -> 8537
A26: Ago | B26: =IFERROR(__xludf.DUMMYFUNCTION("IFERROR(XLOOKUP(MAX(FILTER('Datos diarios'!$A$2:$A$366,'Datos diarios'!$A$2:$A$366>=DATE(2026,8,1),'Datos diarios'!$A$2:$A$366<DATE(2026,9,1),'Datos diarios'!$B$2:$B$366<>"""")),'Datos diarios'!$A$2:$A$366,'Datos diarios'!$B$2:$B$366,""""),"""")"),86713) -> 86713 | C26: =B25 -> 83862 | D26: =IF(AND(B26="",COUNTIFS(Movimientos!$D$6:$D$505,">="&DATE(2026,8,1),Movimientos!$D$6:$D$505,"<"&DATE(2026,9,1))=0),"",SUMIFS(Movimientos!$B$6:$B$505,Movimientos!$D$6:$D$505,">="&DATE(2026,8,1),Movimientos!$D$6:$D$505,"<"&DATE(2026,9,1))) -> 1508 | E26: =IF(B26="","",B26-C26-IF(D26="",0,D26)) -> 1343 | F26: =IF(OR(B26="",C26=0),"",((B26-IF(D26="",0,D26))/C26-1)*100) -> 1.6014405 | G26: =IF(F26="","",((1+G25/100)*(1+F26/100)-1)*100) -> 11.490344 | T26: =A27 -> Sep | U26: =IF(B27="","",B27) -> 85387 | V26: =IF(U26="","",$C$19+SUM($D$19:D27)) -> 78176 | W26: =IF(U26="","",U26-V26) -> 7211
A27: Sep | B27: =IFERROR(__xludf.DUMMYFUNCTION("IFERROR(XLOOKUP(MAX(FILTER('Datos diarios'!$A$2:$A$366,'Datos diarios'!$A$2:$A$366>=DATE(2026,9,1),'Datos diarios'!$A$2:$A$366<DATE(2026,10,1),'Datos diarios'!$B$2:$B$366<>"""")),'Datos diarios'!$A$2:$A$366,'Datos diarios'!$B$2:$B$366,""""),"""")"),85387) -> 85387 | C27: =B26 -> 86713 | D27: =IF(AND(B27="",COUNTIFS(Movimientos!$D$6:$D$505,">="&DATE(2026,9,1),Movimientos!$D$6:$D$505,"<"&DATE(2026,10,1))=0),"",SUMIFS(Movimientos!$B$6:$B$505,Movimientos!$D$6:$D$505,">="&DATE(2026,9,1),Movimientos!$D$6:$D$505,"<"&DATE(2026,10,1))) -> 0 | E27: =IF(B27="","",B27-C27-IF(D27="",0,D27)) -> -1326 | F27: =IF(OR(B27="",C27=0),"",((B27-IF(D27="",0,D27))/C27-1)*100) -> -1.5291825 | G27: =IF(F27="","",((1+G26/100)*(1+F27/100)-1)*100) -> 9.7854537 | T27: =A28 -> Oct | U27: =IF(B28="","",B28) | V27: =IF(U27="","",$C$19+SUM($D$19:D28)) | W27: =IF(U27="","",U27-V27)
A28: Oct | B28: =IFERROR(__xludf.DUMMYFUNCTION("IFERROR(XLOOKUP(MAX(FILTER('Datos diarios'!$A$2:$A$366,'Datos diarios'!$A$2:$A$366>=DATE(2026,10,1),'Datos diarios'!$A$2:$A$366<DATE(2026,11,1),'Datos diarios'!$B$2:$B$366<>"""")),'Datos diarios'!$A$2:$A$366,'Datos diarios'!$B$2:$B$366,""""),"""")"),"") | C28: =B27 -> 85387 | D28: =IF(AND(B28="",COUNTIFS(Movimientos!$D$6:$D$505,">="&DATE(2026,10,1),Movimientos!$D$6:$D$505,"<"&DATE(2026,11,1))=0),"",SUMIFS(Movimientos!$B$6:$B$505,Movimientos!$D$6:$D$505,">="&DATE(2026,10,1),Movimientos!$D$6:$D$505,"<"&DATE(2026,11,1))) | E28: =IF(B28="","",B28-C28-IF(D28="",0,D28)) | F28: =IF(OR(B28="",C28=0),"",((B28-IF(D28="",0,D28))/C28-1)*100) | G28: =IF(F28="","",((1+G27/100)*(1+F28/100)-1)*100) | T28: =A29 -> Nov | U28: =IF(B29="","",B29) | V28: =IF(U28="","",$C$19+SUM($D$19:D29)) | W28: =IF(U28="","",U28-V28)
A29: Nov | B29: =IFERROR(__xludf.DUMMYFUNCTION("IFERROR(XLOOKUP(MAX(FILTER('Datos diarios'!$A$2:$A$366,'Datos diarios'!$A$2:$A$366>=DATE(2026,11,1),'Datos diarios'!$A$2:$A$366<DATE(2026,12,1),'Datos diarios'!$B$2:$B$366<>"""")),'Datos diarios'!$A$2:$A$366,'Datos diarios'!$B$2:$B$366,""""),"""")"),"") | C29: =B28 | D29: =IF(AND(B29="",COUNTIFS(Movimientos!$D$6:$D$505,">="&DATE(2026,11,1),Movimientos!$D$6:$D$505,"<"&DATE(2026,12,1))=0),"",SUMIFS(Movimientos!$B$6:$B$505,Movimientos!$D$6:$D$505,">="&DATE(2026,11,1),Movimientos!$D$6:$D$505,"<"&DATE(2026,12,1))) | E29: =IF(B29="","",B29-C29-IF(D29="",0,D29)) | F29: =IF(OR(B29="",C29=0),"",((B29-IF(D29="",0,D29))/C29-1)*100) | G29: =IF(F29="","",((1+G28/100)*(1+F29/100)-1)*100) | T29: =A30 -> Dic | U29: =IF(B30="","",B30) | V29: =IF(U29="","",$C$19+SUM($D$19:D30)) | W29: =IF(U29="","",U29-V29)
A30: Dic | B30: =IFERROR(__xludf.DUMMYFUNCTION("IFERROR(XLOOKUP(MAX(FILTER('Datos diarios'!$A$2:$A$366,'Datos diarios'!$A$2:$A$366>=DATE(2026,12,1),'Datos diarios'!$A$2:$A$366<DATE(2027,1,1),'Datos diarios'!$B$2:$B$366<>"""")),'Datos diarios'!$A$2:$A$366,'Datos diarios'!$B$2:$B$366,""""),"""")"),"") | C30: =B29 | D30: =IF(AND(B30="",COUNTIFS(Movimientos!$D$6:$D$505,">="&DATE(2026,12,1),Movimientos!$D$6:$D$505,"<"&DATE(2026,13,1))=0),"",SUMIFS(Movimientos!$B$6:$B$505,Movimientos!$D$6:$D$505,">="&DATE(2026,12,1),Movimientos!$D$6:$D$505,"<"&DATE(2026,13,1))) | E30: =IF(B30="","",B30-C30-IF(D30="",0,D30)) | F30: =IF(OR(B30="",C30=0),"",((B30-IF(D30="",0,D30))/C30-1)*100) | G30: =IF(F30="","",((1+G29/100)*(1+F30/100)-1)*100)
A31: YTD 2026 | B31: =IFERROR(__xludf.DUMMYFUNCTION("IFERROR(INDEX(FILTER(B19:B30,ISNUMBER(B19:B30)),COUNT(FILTER(B19:B30,ISNUMBER(B19:B30)))),"""")"),85387) -> 85387 | C31: =C19 -> 73708 | D31: =SUM(D19:D30) -> 4468 | E31: =SUM(E19:E30) -> 7211 | F31: =IF(OR(B31="",C31=0),"",(B31-C31-D31)/C31) -> 0.097831986 | G31: =IFERROR(__xludf.DUMMYFUNCTION("IFERROR(INDEX(FILTER(G19:G30,ISNUMBER(G19:G30)),COUNT(FILTER(G19:G30,ISNUMBER(G19:G30)))),"""")"),9.78545366884213) -> 9.7854537
A32: Volatilidad híbrida | B32: =IFERROR(__xludf.DUMMYFUNCTION("LET(m,FILTER(F19:F24,ISNUMBER(F19:F24)),d,FILTER('Datos diarios'!D2:D366,'Datos diarios'!A2:A366>=DATE(2026,7,7),'Datos diarios'!A2:A366<=TODAY(),ISNUMBER('Datos diarios'!D2:D366)),vm,VAR(m)*12/10000,vd,VAR(d)*365/10000,wm,COUNT(m)/12,wd,COUNT(d)/365,SQRT"&"((vm*wm+vd*wd)/(wm+wd)))"),0.127843428409182) -> 0.12784343 | C32: =IFERROR(__xludf.DUMMYFUNCTION("""6 meses · ""&COUNT(FILTER('Datos diarios'!D2:D366,'Datos diarios'!A2:A366>=DATE(2026,7,7),'Datos diarios'!A2:A366<=TODAY(),ISNUMBER('Datos diarios'!D2:D366)))&"" días"""),"6 meses · 54 días") -> 6 meses · 54 días
A34: 2027
A35: Mes | B35: Valor Total | C35: Capital Inicial | D35: Capital Aportado | E35: Plusvalías | F35: % mes / simple YTD | G35: TWR acumulado
A36: Ene | C36: =B30 | D36: =IF(AND(B36="",COUNTIFS(Movimientos!$D$6:$D$505,">="&DATE(2027,1,1),Movimientos!$D$6:$D$505,"<"&DATE(2027,2,1))=0),"",SUMIFS(Movimientos!$B$6:$B$505,Movimientos!$D$6:$D$505,">="&DATE(2027,1,1),Movimientos!$D$6:$D$505,"<"&DATE(2027,2,1))) | E36: =IF(B36="","",B36-C36-IF(D36="",0,D36)) | F36: =IF(OR(B36="",C36=0),"",((B36-IF(D36="",0,D36))/C36-1)*100) | G36: =IF(F36="","",F36)
A37: Feb | C37: =B36 -> 0 | D37: =IF(AND(B37="",COUNTIFS(Movimientos!$D$6:$D$505,">="&DATE(2027,2,1),Movimientos!$D$6:$D$505,"<"&DATE(2027,3,1))=0),"",SUMIFS(Movimientos!$B$6:$B$505,Movimientos!$D$6:$D$505,">="&DATE(2027,2,1),Movimientos!$D$6:$D$505,"<"&DATE(2027,3,1))) | E37: =IF(B37="","",B37-C37-IF(D37="",0,D37)) | F37: =IF(OR(B37="",C37=0),"",((B37-IF(D37="",0,D37))/C37-1)*100) | G37: =IF(F37="","",((1+G36/100)*(1+F37/100)-1)*100)
A38: Mar | C38: =B37 -> 0 | D38: =IF(AND(B38="",COUNTIFS(Movimientos!$D$6:$D$505,">="&DATE(2027,3,1),Movimientos!$D$6:$D$505,"<"&DATE(2027,4,1))=0),"",SUMIFS(Movimientos!$B$6:$B$505,Movimientos!$D$6:$D$505,">="&DATE(2027,3,1),Movimientos!$D$6:$D$505,"<"&DATE(2027,4,1))) | E38: =IF(B38="","",B38-C38-IF(D38="",0,D38)) | F38: =IF(OR(B38="",C38=0),"",((B38-IF(D38="",0,D38))/C38-1)*100) | G38: =IF(F38="","",((1+G37/100)*(1+F38/100)-1)*100)
A39: Abr | C39: =B38 -> 0 | D39: =IF(AND(B39="",COUNTIFS(Movimientos!$D$6:$D$505,">="&DATE(2027,4,1),Movimientos!$D$6:$D$505,"<"&DATE(2027,5,1))=0),"",SUMIFS(Movimientos!$B$6:$B$505,Movimientos!$D$6:$D$505,">="&DATE(2027,4,1),Movimientos!$D$6:$D$505,"<"&DATE(2027,5,1))) | E39: =IF(B39="","",B39-C39-IF(D39="",0,D39)) | F39: =IF(OR(B39="",C39=0),"",((B39-IF(D39="",0,D39))/C39-1)*100) | G39: =IF(F39="","",((1+G38/100)*(1+F39/100)-1)*100)
A40: May | C40: =B39 -> 0 | D40: =IF(AND(B40="",COUNTIFS(Movimientos!$D$6:$D$505,">="&DATE(2027,5,1),Movimientos!$D$6:$D$505,"<"&DATE(2027,6,1))=0),"",SUMIFS(Movimientos!$B$6:$B$505,Movimientos!$D$6:$D$505,">="&DATE(2027,5,1),Movimientos!$D$6:$D$505,"<"&DATE(2027,6,1))) | E40: =IF(B40="","",B40-C40-IF(D40="",0,D40)) | F40: =IF(OR(B40="",C40=0),"",((B40-IF(D40="",0,D40))/C40-1)*100) | G40: =IF(F40="","",((1+G39/100)*(1+F40/100)-1)*100)
A41: Jun | C41: =B40 -> 0 | D41: =IF(AND(B41="",COUNTIFS(Movimientos!$D$6:$D$505,">="&DATE(2027,6,1),Movimientos!$D$6:$D$505,"<"&DATE(2027,7,1))=0),"",SUMIFS(Movimientos!$B$6:$B$505,Movimientos!$D$6:$D$505,">="&DATE(2027,6,1),Movimientos!$D$6:$D$505,"<"&DATE(2027,7,1))) | E41: =IF(B41="","",B41-C41-IF(D41="",0,D41)) | F41: =IF(OR(B41="",C41=0),"",((B41-IF(D41="",0,D41))/C41-1)*100) | G41: =IF(F41="","",((1+G40/100)*(1+F41/100)-1)*100)
...

Sheet Diario
A1: DIARIO · 2026
A2: Introduce el valor total de la cartera en amarillo.
A3: Movimientos de dinero → pestaña Movimientos.
A4: Verde: cierre histórico. Gris: fin de semana.
A5: Fecha | B5: Valor € | C5: Estado
A6: 46023 | C6: =IF(B6="",IF(A6>TODAY(),"Pendiente","Sin dato"),IF(A6>TODAY(),"Fecha futura",IF(OR(A6=DATE(2026,1,30),A6=DATE(2026,2,27),A6=DATE(2026,3,31),A6=DATE(2026,4,30),A6=DATE(2026,5,29),A6=DATE(2026,6,30)),"Histórico",IF(WEEKDAY(A6,2)>5,"Fin semana","Registrado")))) -> Sin dato
A7: 46024 | C7: =IF(B7="",IF(A7>TODAY(),"Pendiente","Sin dato"),IF(A7>TODAY(),"Fecha futura",IF(OR(A7=DATE(2026,1,30),A7=DATE(2026,2,27),A7=DATE(2026,3,31),A7=DATE(2026,4,30),A7=DATE(2026,5,29),A7=DATE(2026,6,30)),"Histórico",IF(WEEKDAY(A7,2)>5,"Fin semana","Registrado")))) -> Sin dato
A8: 46025 | C8: =IF(B8="",IF(A8>TODAY(),"Pendiente","Sin dato"),IF(A8>TODAY(),"Fecha futura",IF(OR(A8=DATE(2026,1,30),A8=DATE(2026,2,27),A8=DATE(2026,3,31),A8=DATE(2026,4,30),A8=DATE(2026,5,29),A8=DATE(2026,6,30)),"Histórico",IF(WEEKDAY(A8,2)>5,"Fin semana","Registrado")))) -> Sin dato
A9: 46026 | C9: =IF(B9="",IF(A9>TODAY(),"Pendiente","Sin dato"),IF(A9>TODAY(),"Fecha futura",IF(OR(A9=DATE(2026,1,30),A9=DATE(2026,2,27),A9=DATE(2026,3,31),A9=DATE(2026,4,30),A9=DATE(2026,5,29),A9=DATE(2026,6,30)),"Histórico",IF(WEEKDAY(A9,2)>5,"Fin semana","Registrado")))) -> Sin dato
A10: 46027 | C10: =IF(B10="",IF(A10>TODAY(),"Pendiente","Sin dato"),IF(A10>TODAY(),"Fecha futura",IF(OR(A10=DATE(2026,1,30),A10=DATE(2026,2,27),A10=DATE(2026,3,31),A10=DATE(2026,4,30),A10=DATE(2026,5,29),A10=DATE(2026,6,30)),"Histórico",IF(WEEKDAY(A10,2)>5,"Fin semana","Registrado")))) -> Sin dato
A11: 46028 | C11: =IF(B11="",IF(A11>TODAY(),"Pendiente","Sin dato"),IF(A11>TODAY(),"Fecha futura",IF(OR(A11=DATE(2026,1,30),A11=DATE(2026,2,27),A11=DATE(2026,3,31),A11=DATE(2026,4,30),A11=DATE(2026,5,29),A11=DATE(2026,6,30)),"Histórico",IF(WEEKDAY(A11,2)>5,"Fin semana","Registrado")))) -> Sin dato
A12: 46029 | C12: =IF(B12="",IF(A12>TODAY(),"Pendiente","Sin dato"),IF(A12>TODAY(),"Fecha futura",IF(OR(A12=DATE(2026,1,30),A12=DATE(2026,2,27),A12=DATE(2026,3,31),A12=DATE(2026,4,30),A12=DATE(2026,5,29),A12=DATE(2026,6,30)),"Histórico",IF(WEEKDAY(A12,2)>5,"Fin semana","Registrado")))) -> Sin dato
A13: 46030 | C13: =IF(B13="",IF(A13>TODAY(),"Pendiente","Sin dato"),IF(A13>TODAY(),"Fecha futura",IF(OR(A13=DATE(2026,1,30),A13=DATE(2026,2,27),A13=DATE(2026,3,31),A13=DATE(2026,4,30),A13=DATE(2026,5,29),A13=DATE(2026,6,30)),"Histórico",IF(WEEKDAY(A13,2)>5,"Fin semana","Registrado")))) -> Sin dato
A14: 46031 | C14: =IF(B14="",IF(A14>TODAY(),"Pendiente","Sin dato"),IF(A14>TODAY(),"Fecha futura",IF(OR(A14=DATE(2026,1,30),A14=DATE(2026,2,27),A14=DATE(2026,3,31),A14=DATE(2026,4,30),A14=DATE(2026,5,29),A14=DATE(2026,6,30)),"Histórico",IF(WEEKDAY(A14,2)>5,"Fin semana","Registrado")))) -> Sin dato
A15: 46032 | C15: =IF(B15="",IF(A15>TODAY(),"Pendiente","Sin dato"),IF(A15>TODAY(),"Fecha futura",IF(OR(A15=DATE(2026,1,30),A15=DATE(2026,2,27),A15=DATE(2026,3,31),A15=DATE(2026,4,30),A15=DATE(2026,5,29),A15=DATE(2026,6,30)),"Histórico",IF(WEEKDAY(A15,2)>5,"Fin semana","Registrado")))) -> Sin dato
A16: 46033 | C16: =IF(B16="",IF(A16>TODAY(),"Pendiente","Sin dato"),IF(A16>TODAY(),"Fecha futura",IF(OR(A16=DATE(2026,1,30),A16=DATE(2026,2,27),A16=DATE(2026,3,31),A16=DATE(2026,4,30),A16=DATE(2026,5,29),A16=DATE(2026,6,30)),"Histórico",IF(WEEKDAY(A16,2)>5,"Fin semana","Registrado")))) -> Sin dato
A17: 46034 | C17: =IF(B17="",IF(A17>TODAY(),"Pendiente","Sin dato"),IF(A17>TODAY(),"Fecha futura",IF(OR(A17=DATE(2026,1,30),A17=DATE(2026,2,27),A17=DATE(2026,3,31),A17=DATE(2026,4,30),A17=DATE(2026,5,29),A17=DATE(2026,6,30)),"Histórico",IF(WEEKDAY(A17,2)>5,"Fin semana","Registrado")))) -> Sin dato
... A34: 46051 | C34: =IF(B34="",IF(A34>TODAY(),"Pendiente","Sin dato"),IF(A34>TODAY(),"Fecha futura",IF(OR(A34=DATE(2026,1,30),A34=DATE(2026,2,27),A34=DATE(2026,3,31),A34=DATE(2026,4,30),A34=DATE(2026,5,29),A34=DATE(2026,6,30)),"Histórico",IF(WEEKDAY(A34,2)>5,"Fin semana","Registrado")))) -> Sin dato
A35: 46052 | B35: =Evolucion!B19 -> 76000 | C35: =IF(B35="",IF(A35>TODAY(),"Pendiente","Sin dato"),IF(A35>TODAY(),"Fecha futura",IF(OR(A35=DATE(2026,1,30),A35=DATE(2026,2,27),A35=DATE(2026,3,31),A35=DATE(2026,4,30),A35=DATE(2026,5,29),A35=DATE(2026,6,30)),"Histórico",IF(WEEKDAY(A35,2)>5,"Fin semana","Registrado")))) -> Histórico
A36: 46053 | C36: =IF(B36="",IF(A36>TODAY(),"Pendiente","Sin dato"),IF(A36>TODAY(),"Fecha futura",IF(OR(A36=DATE(2026,1,30),A36=DATE(2026,2,27),A36=DATE(2026,3,31),A36=DATE(2026,4,30),A36=DATE(2026,5,29),A36=DATE(2026,6,30)),"Histórico",IF(WEEKDAY(A36,2)>5,"Fin semana","Registrado")))) -> Sin dato
A37: 46054 | C37: =IF(B37="",IF(A37>TODAY(),"Pendiente","Sin dato"),IF(A37>TODAY(),"Fecha futura",IF(OR(A37=DATE(2026,1,30),A37=DATE(2026,2,27),A37=DATE(2026,3,31),A37=DATE(2026,4,30),A37=DATE(2026,5,29),A37=DATE(2026,6,30)),"Histórico",IF(WEEKDAY(A37,2)>5,"Fin semana","Registrado")))) -> Sin dato
A38: 46055 | C38: =IF(B38="",IF(A38>TODAY(),"Pendiente","Sin dato"),IF(A38>TODAY(),"Fecha futura",IF(OR(A38=DATE(2026,1,30),A38=DATE(2026,2,27),A38=DATE(2026,3,31),A38=DATE(2026,4,30),A38=DATE(2026,5,29),A38=DATE(2026,6,30)),"Histórico",IF(WEEKDAY(A38,2)>5,"Fin semana","Registrado")))) -> Sin dato
A39: 46056 | C39: =IF(B39="",IF(A39>TODAY(),"Pendiente","Sin dato"),IF(A39>TODAY(),"Fecha futura",IF(OR(A39=DATE(2026,1,30),A39=DATE(2026,2,27),A39=DATE(2026,3,31),A39=DATE(2026,4,30),A39=DATE(2026,5,29),A39=DATE(2026,6,30)),"Histórico",IF(WEEKDAY(A39,2)>5,"Fin semana","Registrado")))) -> Sin dato
A40: 46057 | C40: =IF(B40="",IF(A40>TODAY(),"Pendiente","Sin dato"),IF(A40>TODAY(),"Fecha futura",IF(OR(A40=DATE(2026,1,30),A40=DATE(2026,2,27),A40=DATE(2026,3,31),A40=DATE(2026,4,30),A40=DATE(2026,5,29),A40=DATE(2026,6,30)),"Histórico",IF(WEEKDAY(A40,2)>5,"Fin semana","Registrado")))) -> Sin dato
A41: 46058 | C41: =IF(B41="",IF(A41>TODAY(),"Pendiente","Sin dato"),IF(A41>TODAY(),"Fecha futura",IF(OR(A41=DATE(2026,1,30),A41=DATE(2026,2,27),A41=DATE(2026,3,31),A41=DATE(2026,4,30),A41=DATE(2026,5,29),A41=DATE(2026,6,30)),"Histórico",IF(WEEKDAY(A41,2)>5,"Fin semana","Registrado")))) -> Sin dato
A42: 46059 | C42: =IF(B42="",IF(A42>TODAY(),"Pendiente","Sin dato"),IF(A42>TODAY(),"Fecha futura",IF(OR(A42=DATE(2026,1,30),A42=DATE(2026,2,27),A42=DATE(2026,3,31),A42=DATE(2026,4,30),A42=DATE(2026,5,29),A42=DATE(2026,6,30)),"Histórico",IF(WEEKDAY(A42,2)>5,"Fin semana","Registrado")))) -> Sin dato
A43: 46060 | C43: =IF(B43="",IF(A43>TODAY(),"Pendiente","Sin dato"),IF(A43>TODAY(),"Fecha futura",IF(OR(A43=DATE(2026,1,30),A43=DATE(2026,2,27),A43=DATE(2026,3,31),A43=DATE(2026,4,30),A43=DATE(2026,5,29),A43=DATE(2026,6,30)),"Histórico",IF(WEEKDAY(A43,2)>5,"Fin semana","Registrado")))) -> Sin dato
A44: 46061 | C44: =IF(B44="",IF(A44>TODAY(),"Pendiente","Sin dato"),IF(A44>TODAY(),"Fecha futura",IF(OR(A44=DATE(2026,1,30),A44=DATE(2026,2,27),A44=DATE(2026,3,31),A44=DATE(2026,4,30),A44=DATE(2026,5,29),A44=DATE(2026,6,30)),"Histórico",IF(WEEKDAY(A44,2)>5,"Fin semana","Registrado")))) -> Sin dato
A45: 46062 | C45: =IF(B45="",IF(A45>TODAY(),"Pendiente","Sin dato"),IF(A45>TODAY(),"Fecha futura",IF(OR(A45=DATE(2026,1,30),A45=DATE(2026,2,27),A45=DATE(2026,3,31),A45=DATE(2026,4,30),A45=DATE(2026,5,29),A45=DATE(2026,6,30)),"Histórico",IF(WEEKDAY(A45,2)>5,"Fin semana","Registrado")))) -> Sin dato
A46: 46063 | C46: =IF(B46="",IF(A46>TODAY(),"Pendiente","Sin dato"),IF(A46>TODAY(),"Fecha futura",IF(OR(A46=DATE(2026,1,30),A46=DATE(2026,2,27),A46=DATE(2026,3,31),A46=DATE(2026,4,30),A46=DATE(2026,5,29),A46=DATE(2026,6,30)),"Histórico",IF(WEEKDAY(A46,2)>5,"Fin semana","Registrado")))) -> Sin dato
A47: 46064 | C47: =IF(B47="",IF(A47>TODAY(),"Pendiente","Sin dato"),IF(A47>TODAY(),"Fecha futura",IF(OR(A47=DATE(2026,1,30),A47=DATE(2026,2,27),A47=DATE(2026,3,31),A47=DATE(2026,4,30),A47=DATE(2026,5,29),A47=DATE(2026,6,30)),"Histórico",IF(WEEKDAY(A47,2)>5,"Fin semana","Registrado")))) -> Sin dato
... A62: 46079 | C62: =IF(B62="",IF(A62>TODAY(),"Pendiente","Sin dato"),IF(A62>TODAY(),"Fecha futura",IF(OR(A62=DATE(2026,1,30),A62=DATE(2026,2,27),A62=DATE(2026,3,31),A62=DATE(2026,4,30),A62=DATE(2026,5,29),A62=DATE(2026,6,30)),"Histórico",IF(WEEKDAY(A62,2)>5,"Fin semana","Registrado")))) -> Sin dato
A63: 46080 | B63: =Evolucion!B20 -> 76422 | C63: =IF(B63="",IF(A63>TODAY(),"Pendiente","Sin dato"),IF(A63>TODAY(),"Fecha futura",IF(OR(A63=DATE(2026,1,30),A63=DATE(2026,2,27),A63=DATE(2026,3,31),A63=DATE(2026,4,30),A63=DATE(2026,5,29),A63=DATE(2026,6,30)),"Histórico",IF(WEEKDAY(A63,2)>5,"Fin semana","Registrado")))) -> Histórico
A64: 46081 | C64: =IF(B64="",IF(A64>TODAY(),"Pendiente","Sin dato"),IF(A64>TODAY(),"Fecha futura",IF(OR(A64=DATE(2026,1,30),A64=DATE(2026,2,27),A64=DATE(2026,3,31),A64=DATE(2026,4,30),A64=DATE(2026,5,29),A64=DATE(2026,6,30)),"Histórico",IF(WEEKDAY(A64,2)>5,"Fin semana","Registrado")))) -> Sin dato
A65: 46082 | C65: =IF(B65="",IF(A65>TODAY(),"Pendiente","Sin dato"),IF(A65>TODAY(),"Fecha futura",IF(OR(A65=DATE(2026,1,30),A65=DATE(2026,2,27),A65=DATE(2026,3,31),A65=DATE(2026,4,30),A65=DATE(2026,5,29),A65=DATE(2026,6,30)),"Histórico",IF(WEEKDAY(A65,2)>5,"Fin semana","Registrado")))) -> Sin dato
A66: 46083 | C66: =IF(B66="",IF(A66>TODAY(),"Pendiente","Sin dato"),IF(A66>TODAY(),"Fecha futura",IF(OR(A66=DATE(2026,1,30),A66=DATE(2026,2,27),A66=DATE(2026,3,31),A66=DATE(2026,4,30),A66=DATE(2026,5,29),A66=DATE(2026,6,30)),"Histórico",IF(WEEKDAY(A66,2)>5,"Fin semana","Registrado")))) -> Sin dato
A67: 46084 | C67: =IF(B67="",IF(A67>TODAY(),"Pendiente","Sin dato"),IF(A67>TODAY(),"Fecha futura",IF(OR(A67=DATE(2026,1,30),A67=DATE(2026,2,27),A67=DATE(2026,3,31),A67=DATE(2026,4,30),A67=DATE(2026,5,29),A67=DATE(2026,6,30)),"Histórico",IF(WEEKDAY(A67,2)>5,"Fin semana","Registrado")))) -> Sin dato
A68: 46085 | C68: =IF(B68="",IF(A68>TODAY(),"Pendiente","Sin dato"),IF(A68>TODAY(),"Fecha futura",IF(OR(A68=DATE(2026,1,30),A68=DATE(2026,2,27),A68=DATE(2026,3,31),A68=DATE(2026,4,30),A68=DATE(2026,5,29),A68=DATE(2026,6,30)),"Histórico",IF(WEEKDAY(A68,2)>5,"Fin semana","Registrado")))) -> Sin dato
A69: 46086 | C69: =IF(B69="",IF(A69>TODAY(),"Pendiente","Sin dato"),IF(A69>TODAY(),"Fecha futura",IF(OR(A69=DATE(2026,1,30),A69=DATE(2026,2,27),A69=DATE(2026,3,31),A69=DATE(2026,4,30),A69=DATE(2026,5,29),A69=DATE(2026,6,30)),"Histórico",IF(WEEKDAY(A69,2)>5,"Fin semana","Registrado")))) -> Sin dato
A70: 46087 | C70: =IF(B70="",IF(A70>TODAY(),"Pendiente","Sin dato"),IF(A70>TODAY(),"Fecha futura",IF(OR(A70=DATE(2026,1,30),A70=DATE(2026,2,27),A70=DATE(2026,3,31),A70=DATE(2026,4,30),A70=DATE(2026,5,29),A70=DATE(2026,6,30)),"Histórico",IF(WEEKDAY(A70,2)>5,"Fin semana","Registrado")))) -> Sin dato
...

Sheet Movimientos
A1: MOVIMIENTOS
A2: Datos ficticios: una sola entrada por movimiento.
A3: Fecha real o mes AAAA-MM; ingresos +, retiradas −.
A4: Histórico mensual: sustituye el total al detallar sus fechas.
A5: Fecha / mes | B5: Importe € | C5: Concepto | D5: Fecha contable | E5: Fecha exacta
A6: 45716 | B6: 700 | C6: Aportación demo | D6: =IF(A6="","",A6) -> 45716 | E6: =IF(A6="","",ISNUMBER(A6)) -> TRUE
A7: 45747 | B7: 700 | C7: Aportación demo | D7: =IF(A7="","",A7) -> 45747 | E7: =IF(A7="","",ISNUMBER(A7)) -> TRUE
A8: 45777 | B8: 700 | C8: Aportación demo | D8: =IF(A8="","",A8) -> 45777 | E8: =IF(A8="","",ISNUMBER(A8)) -> TRUE
A9: 45807 | B9: 700 | C9: Aportación demo | D9: =IF(A9="","",A9) -> 45807 | E9: =IF(A9="","",ISNUMBER(A9)) -> TRUE
A10: 45838 | B10: 700 | C10: Aportación demo | D10: =IF(A10="","",A10) -> 45838 | E10: =IF(A10="","",ISNUMBER(A10)) -> TRUE
A11: 45869 | B11: 700 | C11: Aportación demo | D11: =IF(A11="","",A11) -> 45869 | E11: =IF(A11="","",ISNUMBER(A11)) -> TRUE
A12: 45898 | B12: 700 | C12: Aportación demo | D12: =IF(A12="","",A12) -> 45898 | E12: =IF(A12="","",ISNUMBER(A12)) -> TRUE
A13: 45930 | B13: 700 | C13: Aportación demo | D13: =IF(A13="","",A13) -> 45930 | E13: =IF(A13="","",ISNUMBER(A13)) -> TRUE
A14: 45961 | B14: 700 | C14: Aportación demo | D14: =IF(A14="","",A14) -> 45961 | E14: =IF(A14="","",ISNUMBER(A14)) -> TRUE
A15: 45989 | B15: 700 | C15: Aportación demo | D15: =IF(A15="","",A15) -> 45989 | E15: =IF(A15="","",ISNUMBER(A15)) -> TRUE
A16: 46022 | B16: 700 | C16: Aportación demo | D16: =IF(A16="","",A16) -> 46022 | E16: =IF(A16="","",ISNUMBER(A16)) -> TRUE
A17: 46052 | B17: 500 | C17: Aportación demo | D17: =IF(A17="","",A17) -> 46052 | E17: =IF(A17="","",ISNUMBER(A17)) -> TRUE
... A24: 46260 | B24: 1508 | C24: Aportación demo | D24: =IF(A24="","",A24) -> 46260 | E24: =IF(A24="","",ISNUMBER(A24)) -> TRUE
D25: =IF(A25="","",IF(ISNUMBER(A25),A25,IFERROR(DATE(VALUE(LEFT(A25,4)),VALUE(RIGHT(A25,2)),1),""))) | E25: =IF(A25="","",ISNUMBER(A25))
D26: =IF(A26="","",IF(ISNUMBER(A26),A26,IFERROR(DATE(VALUE(LEFT(A26,4)),VALUE(RIGHT(A26,2)),1),""))) | E26: =IF(A26="","",ISNUMBER(A26))
D27: =IF(A27="","",IF(ISNUMBER(A27),A27,IFERROR(DATE(VALUE(LEFT(A27,4)),VALUE(RIGHT(A27,2)),1),""))) | E27: =IF(A27="","",ISNUMBER(A27))
D28: =IF(A28="","",IF(ISNUMBER(A28),A28,IFERROR(DATE(VALUE(LEFT(A28,4)),VALUE(RIGHT(A28,2)),1),""))) | E28: =IF(A28="","",ISNUMBER(A28))
D29: =IF(A29="","",IF(ISNUMBER(A29),A29,IFERROR(DATE(VALUE(LEFT(A29,4)),VALUE(RIGHT(A29,2)),1),""))) | E29: =IF(A29="","",ISNUMBER(A29))
D30: =IF(A30="","",IF(ISNUMBER(A30),A30,IFERROR(DATE(VALUE(LEFT(A30,4)),VALUE(RIGHT(A30,2)),1),""))) | E30: =IF(A30="","",ISNUMBER(A30))
D31: =IF(A31="","",IF(ISNUMBER(A31),A31,IFERROR(DATE(VALUE(LEFT(A31,4)),VALUE(RIGHT(A31,2)),1),""))) | E31: =IF(A31="","",ISNUMBER(A31))
D32: =IF(A32="","",IF(ISNUMBER(A32),A32,IFERROR(DATE(VALUE(LEFT(A32,4)),VALUE(RIGHT(A32,2)),1),""))) | E32: =IF(A32="","",ISNUMBER(A32))
D33: =IF(A33="","",IF(ISNUMBER(A33),A33,IFERROR(DATE(VALUE(LEFT(A33,4)),VALUE(RIGHT(A33,2)),1),""))) | E33: =IF(A33="","",ISNUMBER(A33))
D34: =IF(A34="","",IF(ISNUMBER(A34),A34,IFERROR(DATE(VALUE(LEFT(A34,4)),VALUE(RIGHT(A34,2)),1),""))) | E34: =IF(A34="","",ISNUMBER(A34))
D35: =IF(A35="","",IF(ISNUMBER(A35),A35,IFERROR(DATE(VALUE(LEFT(A35,4)),VALUE(RIGHT(A35,2)),1),""))) | E35: =IF(A35="","",ISNUMBER(A35))
D36: =IF(A36="","",IF(ISNUMBER(A36),A36,IFERROR(DATE(VALUE(LEFT(A36,4)),VALUE(RIGHT(A36,2)),1),""))) | E36: =IF(A36="","",ISNUMBER(A36))
... D505: =IF(A505="","",IF(ISNUMBER(A505),A505,IFERROR(DATE(VALUE(LEFT(A505,4)),VALUE(RIGHT(A505,2)),1),""))) | E505: =IF(A505="","",ISNUMBER(A505))

Sheet Comparativa
A1: Año | B1: Mes | C1: Periodo | D1: Rentabilidad Cartera (%) | E1: Rentabilidad MSCI World (%) | F1: Cartera Acum (%) | G1: MSCI Acum (%)
A2: 2025 | B2: Feb | C2: =A2&" "&B2 -> 2025 Feb | D2: =IF(OR(Evolucion!B3="",(Evolucion!C3+IF(Evolucion!D3="",0,Evolucion!D3))=0),"",TRUNC((Evolucion!B3-(Evolucion!C3+IF(Evolucion!D3="",0,Evolucion!D3)))/(Evolucion!C3+IF(Evolucion!D3="",0,Evolucion!D3))*100,3)) -> 0 | E2: 0 | F2: =IF(D2="","",D2) -> 0 | G2: =IF(E2="","",E2) -> 0
A3: 2025 | B3: Mar | C3: =A3&" "&B3 -> 2025 Mar | D3: =IF(Evolucion!F4="","",Evolucion!F4) -> 3.8357366 | E3: -6.97 | F3: =IF(D3="","",IF(F2="",D3,((1+F2/100)*(1+D3/100)-1)*100)) -> 3.8357366 | G3: =IF(E3="","",IF(G2="",E3,((1+G2/100)*(1+E3/100)-1)*100)) -> -6.97
A4: 2025 | B4: Abr | C4: =A4&" "&B4 -> 2025 Abr | D4: =IF(Evolucion!F5="","",Evolucion!F5) -> 2.1654364 | E4: -4.12 | F4: =IF(D4="","",IF(F3="",D4,((1+F3/100)*(1+D4/100)-1)*100)) -> 6.0842335 | G4: =IF(E4="","",IF(G3="",E4,((1+G3/100)*(1+E4/100)-1)*100)) -> -10.802836
A5: 2025 | B5: May | C5: =A5&" "&B5 -> 2025 May | D5: =IF(Evolucion!F6="","",Evolucion!F6) -> 2.2706153 | E5: 6.07 | F5: =IF(D5="","",IF(F4="",D5,((1+F4/100)*(1+D5/100)-1)*100)) -> 8.4929983 | G5: =IF(E5="","",IF(G4="",E5,((1+G4/100)*(1+E5/100)-1)*100)) -> -5.3885681
A6: 2025 | B6: Jun | C6: =A6&" "&B6 -> 2025 Jun | D6: =IF(Evolucion!F7="","",Evolucion!F7) -> 1.1130311 | E6: 0.88 | F6: =IF(D6="","",IF(F5="",D6,((1+F5/100)*(1+D6/100)-1)*100)) -> 9.7005591 | G6: =IF(E6="","",IF(G5="",E6,((1+G5/100)*(1+E6/100)-1)*100)) -> -4.5559875
A7: 2025 | B7: Jul | C7: =A7&" "&B7 -> 2025 Jul | D7: =IF(Evolucion!F8="","",Evolucion!F8) -> 1.4954045 | E7: 3.86 | F7: =IF(D7="","",IF(F6="",D7,((1+F6/100)*(1+D7/100)-1)*100)) -> 11.341026 | G7: =IF(E7="","",IF(G6="",E7,((1+G6/100)*(1+E7/100)-1)*100)) -> -0.87184866
A8: 2025 | B8: Ago | C8: =A8&" "&B8 -> 2025 Ago | D8: =IF(Evolucion!F9="","",Evolucion!F9) -> 0.80015487 | E8: 0.32 | F8: =IF(D8="","",IF(F7="",D8,((1+F7/100)*(1+D8/100)-1)*100)) -> 12.231927 | G8: =IF(E8="","",IF(G7="",E8,((1+G7/100)*(1+E8/100)-1)*100)) -> -0.55463858
A9: 2025 | B9: Sep | C9: =A9&" "&B9 -> 2025 Sep | D9: =IF(Evolucion!F10="","",Evolucion!F10) -> 5.199101 | E9: 2.81 | F9: =IF(D9="","",IF(F8="",D9,((1+F8/100)*(1+D9/100)-1)*100)) -> 18.066978 | G9: =IF(E9="","",IF(G8="",E9,((1+G8/100)*(1+E9/100)-1)*100)) -> 2.2397761
A10: 2025 | B10: Oct | C10: =A10&" "&B10 -> 2025 Oct | D10: =IF(Evolucion!F11="","",Evolucion!F11) -> 2.8539951 | E10: 3.83 | F10: =IF(D10="","",IF(F9="",D10,((1+F9/100)*(1+D10/100)-1)*100)) -> 21.436604 | G10: =IF(E10="","",IF(G9="",E10,((1+G9/100)*(1+E10/100)-1)*100)) -> 6.1555595
A11: 2025 | B11: Nov | C11: =A11&" "&B11 -> 2025 Nov | D11: =IF(Evolucion!F12="","",Evolucion!F12) -> -0.26796206 | E11: -0.27 | F11: =IF(D11="","",IF(F10="",D11,((1+F10/100)*(1+D11/100)-1)*100)) -> 21.1112 | G11: =IF(E11="","",IF(G10="",E11,((1+G10/100)*(1+E11/100)-1)*100)) -> 5.8689395
A12: 2025 | B12: Dic | C12: =A12&" "&B12 -> 2025 Dic | D12: =IF(Evolucion!F13="","",Evolucion!F13) -> 3.8535399 | E12: -0.4 | F12: =IF(D12="","",IF(F11="",D12,((1+F11/100)*(1+D12/100)-1)*100)) -> 25.778268 | G12: =IF(E12="","",IF(G11="",E12,((1+G11/100)*(1+E12/100)-1)*100)) -> 5.4454637
A13: 2026 | B13: Ene | C13: =A13&" "&B13 -> 2026 Ene | D13: =IF(Evolucion!F19="","",Evolucion!F19) -> 2.4312151 | E13: 0.92 | F13: =IF(D13="","",IF(F12="",D13,((1+F12/100)*(1+D13/100)-1)*100)) -> 28.836209 | G13: =IF(E13="","",IF(G12="",E13,((1+G12/100)*(1+E13/100)-1)*100)) -> 6.415562
A14: 2026 | B14: Feb | C14: =A14&" "&B14 -> 2026 Feb | D14: =IF(Evolucion!F20="","",Evolucion!F20) -> -0.36578947 | E14: 1.49 | F14: =IF(D14="","",IF(F13="",D14,((1+F13/100)*(1+D14/100)-1)*100)) -> 28.364939 | G14: =IF(E14="","",IF(G13="",E14,((1+G13/100)*(1+E14/100)-1)*100)) -> 8.0011539
A15: 2026 | B15: Mar | C15: =A15&" "&B15 -> 2026 Mar | D15: =IF(Evolucion!F21="","",Evolucion!F21) -> -5.3283086 | E15: -4.04 | F15: =IF(D15="","",IF(F14="",D15,((1+F14/100)*(1+D15/100)-1)*100)) -> 21.525259 | G15: =IF(E15="","",IF(G14="",E15,((1+G14/100)*(1+E15/100)-1)*100)) -> 3.6379073
A16: 2026 | B16: Abr | C16: =A16&" "&B16 -> 2026 Abr | D16: =IF(Evolucion!F22="","",Evolucion!F22) -> 5.4242632 | E16: 7.65 | F16: =IF(D16="","",IF(F15="",D16,((1+F15/100)*(1+D16/100)-1)*100)) -> 28.117109 | G16: =IF(E16="","",IF(G15="",E16,((1+G15/100)*(1+E16/100)-1)*100)) -> 11.566207
A17: 2026 | B17: May | C17: =A17&" "&B17 -> 2026 May | D17: =IF(Evolucion!F23="","",Evolucion!F23) -> 5.2199929 | E17: 5.1 | F17: =IF(D17="","",IF(F16="",D17,((1+F16/100)*(1+D17/100)-1)*100)) -> 34.804813 | G17: =IF(E17="","",IF(G16="",E17,((1+G16/100)*(1+E17/100)-1)*100)) -> 17.256084
A18: 2026 | B18: Jun | C18: =A18&" "&B18 -> 2026 Jun | D18: =IF(Evolucion!F24="","",Evolucion!F24) -> 0.088066931 | E18: 1.33 | F18: =IF(D18="","",IF(F17="",D18,((1+F17/100)*(1+D18/100)-1)*100)) -> 34.923532 | G18: =IF(E18="","",IF(G17="",E18,((1+G17/100)*(1+E18/100)-1)*100)) -> 18.81559
A19: 2026 | B19: Jul | C19: =A19&" "&B19 -> 2026 Jul | D19: =IF(Evolucion!F25="","",Evolucion!F25) -> 2.2952112 | E19: -0.14 | F19: =IF(D19="","",IF(F18="",D19,((1+F18/100)*(1+D19/100)-1)*100)) -> 38.020312 | G19: =IF(E19="","",IF(G18="",E19,((1+G18/100)*(1+E19/100)-1)*100)) -> 18.649248
A20: 2026 | B20: Ago | C20: =A20&" "&B20 -> 2026 Ago | D20: =IF(Evolucion!F26="","",Evolucion!F26) -> 1.6014405 | E20: 1.59 | F20: =IF(D20="","",IF(F19="",D20,((1+F19/100)*(1+D20/100)-1)*100)) -> 40.230625 | G20: =IF(E20="","",IF(G19="",E20,((1+G19/100)*(1+E20/100)-1)*100)) -> 20.535771
A21: 2026 | B21: Sep | C21: =A21&" "&B21 -> 2026 Sep | D21: =IF(Evolucion!F27="","",Evolucion!F27) -> -1.5291825 | E21: -0.82 | F21: =IF(D21="","",IF(F20="",D21,((1+F20/100)*(1+D21/100)-1)*100)) -> 38.086242 | G21: =IF(E21="","",IF(G20="",E21,((1+G20/100)*(1+E21/100)-1)*100)) -> 19.547378
A22: 2026 | B22: Oct | C22: =A22&" "&B22 -> 2026 Oct | D22: =IF(Evolucion!F28="","",Evolucion!F28) | F22: =IF(D22="","",IF(F21="",D22,((1+F21/100)*(1+D22/100)-1)*100)) | G22: =IF(E22="","",IF(G21="",E22,((1+G21/100)*(1+E22/100)-1)*100))
A23: 2026 | B23: Nov | C23: =A23&" "&B23 -> 2026 Nov | D23: =IF(Evolucion!F29="","",Evolucion!F29) | F23: =IF(D23="","",IF(F22="",D23,((1+F22/100)*(1+D23/100)-1)*100)) | G23: =IF(E23="","",IF(G22="",E23,((1+G22/100)*(1+E23/100)-1)*100))
A24: 2026 | B24: Dic | C24: =A24&" "&B24 -> 2026 Dic | D24: =IF(Evolucion!F30="","",Evolucion!F30) | F24: =IF(D24="","",IF(F23="",D24,((1+F23/100)*(1+D24/100)-1)*100)) | G24: =IF(E24="","",IF(G23="",E24,((1+G23/100)*(1+E24/100)-1)*100))

Sheet Objetivos
A1: OBJETIVOS Y APORTACIONES
A2: Referencia inicial = pesos actuales; edita tus objetivos.
A3: Próxima aportación € | C3: 0
A4: Reparto proporcional al déficit, sin vender posiciones.
A5: Activo | B5: Actual | C5: Objetivo
A6: =Cartera!A2 -> ETF Global Desarrollado | B6: =Cartera!C2 -> 0.23422769 | C6: 0.24579613
A7: =Cartera!A3 -> ETF Mercados Emergentes | B7: =Cartera!C3 -> 0.081979692 | C7: 0.079079207
A8: =Cartera!A4 -> Fondo Asia Pacífico | B8: =Cartera!C4 -> 0.029278462 | C8: 0.026290154
A9: =Cartera!A5 -> Fondo Value Global | B9: =Cartera!C5 -> 0.087835385 | C9: 0.081734895
A10: =Cartera!A6 -> Fondo Internacional A | B10: =Cartera!C6 -> 0.058556923 | C10: 0.059909544
A11: =Cartera!A7 -> Fondo Internacional B | B11: =Cartera!C7 -> 0.023422769 | C11: 0.024075148
A12: =Cartera!A8 -> Fondo Crédito Flexible | B12: =Cartera!C8 -> 0.058556923 | C12: 0.057659747
A13: =Cartera!A9 -> Fondo Mixto Defensivo | B13: =Cartera!C9 -> 0.099546769 | C13: 0.098144497
A14: =Cartera!A10 -> Fondo Retorno Absoluto | B14: =Cartera!C10 -> 0.035134154 | C14: 0.036924504
A15: =Cartera!A11 -> Cuenta de efectivo | B15: =Cartera!C11 -> 0.01624369 | C15: 0
A16: =Cartera!A12 -> Acción tecnológica | B16: =Cartera!C12 -> 0.17567077 | C16: 0.17781515
A17: =Cartera!A13 -> Acción industrial | B17: =Cartera!C13 -> 0.021080492 | C17: 0.021883335
... A20: =Cartera!A16 -> Bitcoin | B20: =Cartera!C16 -> 0.011711385 | C20: 0.012756581
A21: TOTAL | B21: =SUM(B6:B20) -> 1 | C21: =SUM(C6:C20) -> 1
A22: Estado | C22: =IF(AND(COUNT(C6:C20)=15,ABS(C21-1)<0.000001,MIN(C6:C20)>=0,MAX(C6:C20)<=1),"OK","REVISAR") -> OK
A23: Cambia el importe de C3 para simular una aportación.
A25: Activo | B25: Falta € | C25: Aportar €
A26: =A6 -> ETF Global Desarrollado | B26: =IF($C$22<>"OK","",MAX(0,$C6*(Cartera!$B$17+$C$3)-Cartera!B2)) -> 987.79387 | C26: =IF(OR($C$22<>"OK",NOT(ISNUMBER($C$3)),$C$3<0),"",IF(SUM($B$26:$B$40)=0,0,$C$3*B26/SUM($B$26:$B$40))) -> 0
A27: =A7 -> ETF Mercados Emergentes | B27: =IF($C$22<>"OK","",MAX(0,$C7*(Cartera!$B$17+$C$3)-Cartera!B3)) -> 0 | C27: =IF(OR($C$22<>"OK",NOT(ISNUMBER($C$3)),$C$3<0),"",IF(SUM($B$26:$B$40)=0,0,$C$3*B27/SUM($B$26:$B$40))) -> 0
A28: =A8 -> Fondo Asia Pacífico | B28: =IF($C$22<>"OK","",MAX(0,$C8*(Cartera!$B$17+$C$3)-Cartera!B4)) -> 0 | C28: =IF(OR($C$22<>"OK",NOT(ISNUMBER($C$3)),$C$3<0),"",IF(SUM($B$26:$B$40)=0,0,$C$3*B28/SUM($B$26:$B$40))) -> 0
A29: =A9 -> Fondo Value Global | B29: =IF($C$22<>"OK","",MAX(0,$C9*(Cartera!$B$17+$C$3)-Cartera!B5)) -> 0 | C29: =IF(OR($C$22<>"OK",NOT(ISNUMBER($C$3)),$C$3<0),"",IF(SUM($B$26:$B$40)=0,0,$C$3*B29/SUM($B$26:$B$40))) -> 0
A30: =A10 -> Fondo Internacional A | B30: =IF($C$22<>"OK","",MAX(0,$C10*(Cartera!$B$17+$C$3)-Cartera!B6)) -> 115.49625 | C30: =IF(OR($C$22<>"OK",NOT(ISNUMBER($C$3)),$C$3<0),"",IF(SUM($B$26:$B$40)=0,0,$C$3*B30/SUM($B$26:$B$40))) -> 0
A31: =A11 -> Fondo Internacional B | B31: =IF($C$22<>"OK","",MAX(0,$C11*(Cartera!$B$17+$C$3)-Cartera!B7)) -> 55.70465 | C31: =IF(OR($C$22<>"OK",NOT(ISNUMBER($C$3)),$C$3<0),"",IF(SUM($B$26:$B$40)=0,0,$C$3*B31/SUM($B$26:$B$40))) -> 0
A32: =A12 -> Fondo Crédito Flexible | B32: =IF($C$22<>"OK","",MAX(0,$C12*(Cartera!$B$17+$C$3)-Cartera!B8)) -> 0 | C32: =IF(OR($C$22<>"OK",NOT(ISNUMBER($C$3)),$C$3<0),"",IF(SUM($B$26:$B$40)=0,0,$C$3*B32/SUM($B$26:$B$40))) -> 0
A33: =A13 -> Fondo Mixto Defensivo | B33: =IF($C$22<>"OK","",MAX(0,$C13*(Cartera!$B$17+$C$3)-Cartera!B9)) -> 0 | C33: =IF(OR($C$22<>"OK",NOT(ISNUMBER($C$3)),$C$3<0),"",IF(SUM($B$26:$B$40)=0,0,$C$3*B33/SUM($B$26:$B$40))) -> 0
A34: =A14 -> Fondo Retorno Absoluto | B34: =IF($C$22<>"OK","",MAX(0,$C14*(Cartera!$B$17+$C$3)-Cartera!B10)) -> 152.87264 | C34: =IF(OR($C$22<>"OK",NOT(ISNUMBER($C$3)),$C$3<0),"",IF(SUM($B$26:$B$40)=0,0,$C$3*B34/SUM($B$26:$B$40))) -> 0
A35: =A15 -> Cuenta de efectivo | B35: =IF($C$22<>"OK","",MAX(0,$C15*(Cartera!$B$17+$C$3)-Cartera!B11)) -> 0 | C35: =IF(OR($C$22<>"OK",NOT(ISNUMBER($C$3)),$C$3<0),"",IF(SUM($B$26:$B$40)=0,0,$C$3*B35/SUM($B$26:$B$40))) -> 0
A36: =A16 -> Acción tecnológica | B36: =IF($C$22<>"OK","",MAX(0,$C16*(Cartera!$B$17+$C$3)-Cartera!B12)) -> 183.10183 | C36: =IF(OR($C$22<>"OK",NOT(ISNUMBER($C$3)),$C$3<0),"",IF(SUM($B$26:$B$40)=0,0,$C$3*B36/SUM($B$26:$B$40))) -> 0
A37: =A17 -> Acción industrial | B37: =IF($C$22<>"OK","",MAX(0,$C17*(Cartera!$B$17+$C$3)-Cartera!B13)) -> 68.552348 | C37: =IF(OR($C$22<>"OK",NOT(ISNUMBER($C$3)),$C$3<0),"",IF(SUM($B$26:$B$40)=0,0,$C$3*B37/SUM($B$26:$B$40))) -> 0
... A40: =A20 -> Bitcoin | B40: =IF($C$22<>"OK","",MAX(0,$C20*(Cartera!$B$17+$C$3)-Cartera!B16)) -> 89.246202 | C40: =IF(OR($C$22<>"OK",NOT(ISNUMBER($C$3)),$C$3<0),"",IF(SUM($B$26:$B$40)=0,0,$C$3*B40/SUM($B$26:$B$40))) -> 0
A41: TOTAL | B41: =SUM(B26:B40) -> 2609.9543 | C41: =SUM(C26:C40) -> 0
A42: Reparto teórico: los importes se muestran redondeados.

Sheet Estadísticas avanzadas
A1: ESTADÍSTICAS AVANZADAS
A2: Rentabilidades mensuales · solo meses completos
A3: €STR anual / objetivo Sortino | C3: 0.0275
A4: Meses analizados | C4: =I55 -> 18
A5: RENTABILIDAD Y RIESGO
A6: Rentabilidad anualizada | C6: =A55 -> 0.25283895
A7: Volatilidad anualizada | C7: =E55 -> 0.088469613
A8: Máximo drawdown mensual | C8: =A52 -> -0.056746077
A9: Mejor mes | C9: =M55 -> 0.054242632
A10: RENTABILIDAD AJUSTADA AL RIESGO
A11: Sortino | C11: =E49 -> 4.4453847
A12: Sharpe | C12: =A49 -> 2.3028731
A13: Treynor | C13: =A58 -> 0.71742591
A14: COMPARACIÓN CON MSCI WORLD
A15: Beta | C15: =M49 -> 0.28397956
A16: Alpha de Jensen anual | C16: =I49 -> 0.17385018
A17: Tracking error anual | C17: =I52 -> 0.12147204
A18: Information ratio | C18: =E52 -> 0.81089411
A19: Correlación | C19: =M52 -> 0.40649275
A20: CONTEXTO DEL SORTINO
A21: Objetivo mensual | C21: =C3/12 -> 0.0022916667
A22: Meses bajo objetivo | C22: =COUNTIF(J77:J98,"<0") -> 4
A23: Proporción bajo objetivo | C23: =IFERROR(C22/C4,"") -> 0.22222222
A24: Muestra corta: los ratios pueden variar mucho.
A25: El drawdown utiliza cierres mensuales.
A26: €STR constante; no reproduce su evolución histórica.
A27: EVOLUCIÓN FRENTE AL BENCHMARK
A41: ESTADÍSTICAS AVANZADAS · PORTFOLIO
A43: €STR anual (tasa libre de riesgo) | C43: =$C$3 -> 0.0275
E44: Objetivo Sortino | G44: =$C$43 -> 0.0275
E45: Meses bajo objetivo | G45: =COUNTIF($J$77:$J$98,"<0") -> 4 | I45: =COUNTIF($J$77:$J$98,"<0")/COUNT($B$77:$B$98) -> 0.22222222
A46: Retornos mensuales en decimales, solo meses completos desde marzo de 2025. Febrero es la base. €STR constante de C3, convertido a mensual como C3/12. Ratios anualizados; drawdown entre cierres mensuales.
A48: Ratio Sharpe | E48: Ratio Sortino | I48: Alpha anual | M48: Beta vs MSCI World
A49: =IFERROR(__xludf.DUMMYFUNCTION("IFERROR(AVERAGE(FILTER($D$77:$D$98,$D$77:$D$98<>""""))/STDEV(FILTER($D$77:$D$98,$D$77:$D$98<>""""))*SQRT(12),"""")"),2.30287314634802) -> 2.3028731 | E49: =IFERROR(__xludf.DUMMYFUNCTION("IFERROR(AVERAGE(FILTER($D$77:$D$98,$D$77:$D$98<>""""))/SQRT(SUMSQ(FILTER($J$77:$J$98,$D$77:$D$98<>""""))/COUNT(FILTER($D$77:$D$98,$D$77:$D$98<>"""")))*SQRT(12),"""")"),4.44538466186077) -> 4.4453847 | I49: =IFERROR(__xludf.DUMMYFUNCTION("IFERROR((AVERAGE(FILTER($B$77:$B$98,$B$77:$B$98<>"""",$C$77:$C$98<>""""))-$C$43/12-$M$49*(AVERAGE(FILTER($C$77:$C$98,$B$77:$B$98<>"""",$C$77:$C$98<>""""))-$C$43/12))*12,"""")"),0.173850180349715) -> 0.17385018 | M49: =IFERROR(__xludf.DUMMYFUNCTION("IFERROR(SLOPE(FILTER($B$77:$B$98,$B$77:$B$98<>"""",$C$77:$C$98<>""""),FILTER($C$77:$C$98,$B$77:$B$98<>"""",$C$77:$C$98<>"""")),"""")"),0.283979564756541) -> 0.28397956
A51: Máximo drawdown | E51: Information ratio | I51: Tracking error anual | M51: Correlación
A52: =IFERROR(MIN($I$77:$I$98),"") -> -0.056746077 | E52: =IFERROR(__xludf.DUMMYFUNCTION("IFERROR(AVERAGE(FILTER($E$77:$E$98,$E$77:$E$98<>""""))/STDEV(FILTER($E$77:$E$98,$E$77:$E$98<>""""))*SQRT(12),"""")"),0.810894112661004) -> 0.81089411 | I52: =IFERROR(__xludf.DUMMYFUNCTION("IFERROR(STDEV(FILTER($E$77:$E$98,$E$77:$E$98<>""""))*SQRT(12),"""")"),0.121472041387777) -> 0.12147204 | M52: =IFERROR(__xludf.DUMMYFUNCTION("IFERROR(CORREL(FILTER($B$77:$B$98,$B$77:$B$98<>"""",$C$77:$C$98<>""""),FILTER($C$77:$C$98,$B$77:$B$98<>"""",$C$77:$C$98<>"""")),"""")"),0.406492745665897) -> 0.40649275
A54: Rentabilidad anualizada | E54: Volatilidad anualizada | I54: Meses analizados | M54: Mejor mes
A55: =IFERROR(__xludf.DUMMYFUNCTION("IFERROR(INDEX(FILTER($F$77:$F$98,$F$77:$F$98<>""""),COUNT(FILTER($F$77:$F$98,$F$77:$F$98<>"""")))^(12/COUNT($B$77:$B$98))-1,"""")"),0.252838946498591) -> 0.25283895 | E55: =IFERROR(__xludf.DUMMYFUNCTION("IFERROR(STDEV(FILTER($B$77:$B$98,$B$77:$B$98<>""""))*SQRT(12),"""")"),0.0884696132180293) -> 0.088469613 | I55: =COUNT($B$77:$B$98) -> 18 | M55: =IFERROR(MAX($B$77:$B$98),"") -> 0.054242632
A57: Ratio Treynor
A58: =IFERROR(__xludf.DUMMYFUNCTION("IFERROR((AVERAGE(FILTER($B$77:$B$98,$B$77:$B$98<>"""",$C$77:$C$98<>""""))*12-$C$43)/$M$49,"""")"),0.717425906058624) -> 0.71742591
...

Sheet Control
A1: CONTROL DE DATOS
A2: Avisos automáticos; revisa los marcados REVISAR.
A3: Pesos de cartera | C3: =IF(AND(COUNT(Cartera!B2:B16)=15,MIN(Cartera!B2:B16)>=0,ABS(SUM(Cartera!C2:C16)-1)<0.000001),"OK","REVISAR") -> OK
A4: Total de cartera | C4: =IF(ABS(Cartera!B17-SUM(Cartera!B2:B16))<0.01,"OK","REVISAR") -> OK
A5: Objetivos suman 100 % | C5: =Objetivos!C22 -> OK
A6: Cuadre mensual | C6: =IF(COUNTIF(K41:K75,"REVISAR")=0,"OK","REVISAR") -> OK
A7: Falta MSCI en mes cerrado | C7: =SUMPRODUCT(N(ISNUMBER(I42:I75)),N(E42:E75<EOMONTH(TODAY(),-1)+1),N(ISNUMBER(J42:J75)=FALSE)) -> 0
A8: Meses cerrados sin cartera | C8: =SUMPRODUCT(N(E42:E75<EOMONTH(TODAY(),-1)+1),N(ISNUMBER(F42:F75)=FALSE)) -> 0
A9: Movimientos incompletos | C9: =SUMPRODUCT(N((LEN(Movimientos!A6:A505)+LEN(Movimientos!B6:B505)+LEN(Movimientos!C6:C505))>0),N((ISNUMBER(Movimientos!D6:D505)*ISNUMBER(Movimientos!B6:B505))=0)) -> 0
A10: Posibles duplicados | C10: =SUMPRODUCT(N(Movimientos!A6:A505<>""),N(COUNTIFS(Movimientos!A6:A505,Movimientos!A6:A505,Movimientos!B6:B505,Movimientos!B6:B505,Movimientos!C6:C505,Movimientos!C6:C505)>1)) -> 0
A11: Históricos sin fecha utilizable | C11: =COUNTIFS(Movimientos!E6:E505,FALSE,Movimientos!C6:C505,"<>Fecha inferida*") -> 0
A12: Cartera − último diario € | C12: =IFERROR(Cartera!B17-LOOKUP(2,1/((Diario!B6:B370<>"")*(Diario!A6:A370<=TODAY())),Diario!B6:B370),"") -> 0
A13: La diferencia puede deberse a fechas de actualización.
A14: Estado general | C14: =IF(OR(COUNTIF(C3:C6,"REVISAR")>0,SUM(C7:C10)>0,C20="REVISAR",C21>0,C23>0),"REVISAR",IF(ABS(C12)>0.01,"AVISO","OK")) -> OK
A15: Supuestos
A16: Mensual: flujos al final del mes.
A17: Diario: días naturales consecutivos; fechas exactas o inferidas identificadas.
A18: €STR constante editable; no es una serie histórica.
A19: Ganancia acumulada desde la base de febrero de 2025.
A20: Comparativa vs Evolución | C20: =IF(AND(ABS(Comparativa!D3/100-I42)<0.00002,ABS(Comparativa!D4/100-I43)<0.00002,ABS(Comparativa!D5/100-I44)<0.00002,ABS(Comparativa!D6/100-I45)<0.00002,ABS(Comparativa!D7/100-I46)<0.00002,ABS(Comparativa!D8/100-I47)<0.00002,ABS(Comparativa!D9/100-I48)<0.00002,ABS(Comparativa!D10/100-I49)<0.00002,ABS(Comparativa!D11/100-I50)<0.00002,ABS(Comparativa!D12/100-I51)<0.00002,ABS(Comparativa!D13/100-I52)<0.00002,ABS(Comparativa!D14/100-I53)<0.00002,ABS(Comparativa!D15/100-I54)<0.00002,ABS(Comparativa!D16/100-I55)<0.00002,ABS(Comparativa!D17/100-I56)<0.00002,ABS(Comparativa!D18/100-I57)<0.00002,ABS(Comparativa!D19/100-I58)<0.00002,ABS(Comparativa!D20/100-I59)<0.00002,ABS(Comparativa!D21/100-I60)<0.00002),"OK","REVISAR") -> OK
A21: Meses con total y detalle | C21: =SUMPRODUCT(N(Movimientos!E6:E505=FALSE),N(Movimientos!A6:A505<>""),N(COUNTIFS(Movimientos!D6:D505,">="&Movimientos!D6:D505,Movimientos!D6:D505,"<"&IFERROR(EOMONTH(Movimientos!D6:D505,0)+1,0),Movimientos!E6:E505,TRUE)>0)) -> 0
A22: Fecha diaria más reciente | C22: =IFERROR(LOOKUP(2,1/((Diario!B6:B370<>"")*(Diario!A6:A370<=TODAY())),Diario!A6:A370),"") -> 46275
A23: Datos diarios con fecha futura | C23: =COUNTIFS(Diario!A6:A370,">"&TODAY(),Diario!B6:B370,">=0") -> 0
E40: Mes | F40: Patrimonio | G40: Capital neto | H40: Ganancia | I40: Retorno | J40: MSCI | K40: Coherencia | L40: Inicial | M40: Flujo neto | N40: Plusvalía mes
